{"bugs": {"703322": {"comments": [{"creator": "nmatsakis@mozilla.com", "author": "nmatsakis@mozilla.com", "count": 0, "is_private": false, "tags": [], "id": 5855983, "bug_id": 703322, "creation_time": "2011-11-17T19:21:37Z", "raw_text": "The TestFailedCtor test case is currently disabled in the cross-thread case because, after its ctor fails, the child process invokes exit() to cleanup.  In the cross-thread case this brings down both the parent and the child.", "text": "The TestFailedCtor test case is currently disabled in the cross-thread case because, after its ctor fails, the child process invokes exit() to cleanup.  In the cross-thread case this brings down both the parent and the child.", "time": "2011-11-17T19:21:37Z", "attachment_id": null}]}}, "comments": {}}